============================= test session starts =============================
platform win32 -- Python 3.12.7, pytest-8.4.1, pluggy-1.6.0 -- C:\Program Files\Python312\python.exe
cachedir: .pytest_cache
metadata: {'Python': '3.12.7', 'Platform': 'Windows-11-10.0.26100-SP0', 'Packages': {'pytest': '8.4.1', 'pluggy': '1.6.0'}, 'Plugins': {'anyio': '3.7.1', 'asyncio': '0.21.1', 'clarity': '1.0.1', 'cov': '4.1.0', 'dependency': '0.6.0', 'env': '1.1.5', 'freezegun': '0.4.2', 'html': '4.1.1', 'instafail': '0.5.0', 'metadata': '3.1.1', 'mock': '3.14.1', 'randomly': '3.16.0', 'sugar': '1.0.0', 'timeout': '2.4.0', 'xdist': '3.8.0'}}
Using --randomly-seed=3572485891
rootdir: C:\Users\User\notefusion-ai\notefusion-ai\backend
configfile: pytest.ini
plugins: anyio-3.7.1, asyncio-0.21.1, clarity-1.0.1, cov-4.1.0, dependency-0.6.0, env-1.1.5, freezegun-0.4.2, html-4.1.1, instafail-0.5.0, metadata-3.1.1, mock-3.14.1, randomly-3.16.0, sugar-1.0.0, timeout-2.4.0, xdist-3.8.0
asyncio: mode=Mode.AUTO
collecting ... collected 2 items

tests/test_hello.py::test_hello PASSED                                   [ 50%]
tests/test_hello.py::test_addition PASSED                                [100%]
INTERNALERROR> Traceback (most recent call last):
INTERNALERROR>   File "C:\Users\User\AppData\Roaming\Python\Python312\site-packages\pluggy\_callers.py", line 43, in run_old_style_hookwrapper
INTERNALERROR>     teardown.send(result)
INTERNALERROR>   File "C:\Users\User\AppData\Roaming\Python\Python312\site-packages\pytest_cov\plugin.py", line 298, in pytest_runtestloop
INTERNALERROR>     self.cov_controller.finish()
INTERNALERROR>   File "C:\Users\User\AppData\Roaming\Python\Python312\site-packages\pytest_cov\engine.py", line 44, in ensure_topdir_wrapper
INTERNALERROR>     return meth(self, *args, **kwargs)
INTERNALERROR>            ^^^^^^^^^^^^^^^^^^^^^^^^^^^
INTERNALERROR>   File "C:\Users\User\AppData\Roaming\Python\Python312\site-packages\pytest_cov\engine.py", line 250, in finish
INTERNALERROR>     self.cov.save()
INTERNALERROR>   File "C:\Users\User\AppData\Roaming\Python\Python312\site-packages\coverage\control.py", line 818, in save
INTERNALERROR>     data = self.get_data()
INTERNALERROR>            ^^^^^^^^^^^^^^^
INTERNALERROR>   File "C:\Users\User\AppData\Roaming\Python\Python312\site-packages\coverage\control.py", line 899, in get_data
INTERNALERROR>     self._post_save_work()
INTERNALERROR>   File "C:\Users\User\AppData\Roaming\Python\Python312\site-packages\coverage\control.py", line 921, in _post_save_work
INTERNALERROR>     self._warn("No data was collected.", slug="no-data-collected")
INTERNALERROR>   File "C:\Users\User\AppData\Roaming\Python\Python312\site-packages\coverage\control.py", line 464, in _warn
INTERNALERROR>     warnings.warn(msg, category=CoverageWarning, stacklevel=2)
INTERNALERROR> coverage.exceptions.CoverageWarning: No data was collected. (no-data-collected)
INTERNALERROR> 
INTERNALERROR> During handling of the above exception, another exception occurred:
INTERNALERROR> 
INTERNALERROR> Traceback (most recent call last):
INTERNALERROR>   File "C:\Users\User\AppData\Roaming\Python\Python312\site-packages\_pytest\main.py", line 289, in wrap_session
INTERNALERROR>     session.exitstatus = doit(config, session) or 0
INTERNALERROR>                          ^^^^^^^^^^^^^^^^^^^^^
INTERNALERROR>   File "C:\Users\User\AppData\Roaming\Python\Python312\site-packages\_pytest\main.py", line 343, in _main
INTERNALERROR>     config.hook.pytest_runtestloop(session=session)
INTERNALERROR>   File "C:\Users\User\AppData\Roaming\Python\Python312\site-packages\pluggy\_hooks.py", line 512, in __call__
INTERNALERROR>     return self._hookexec(self.name, self._hookimpls.copy(), kwargs, firstresult)
INTERNALERROR>            ^^^^^^^^^^^^^^^^^^^^^^^^^^^^^^^^^^^^^^^^^^^^^^^^^^^^^^^^^^^^^^^^^^^^^^
INTERNALERROR>   File "C:\Users\User\AppData\Roaming\Python\Python312\site-packages\pluggy\_manager.py", line 120, in _hookexec
INTERNALERROR>     return self._inner_hookexec(hook_name, methods, kwargs, firstresult)
INTERNALERROR>            ^^^^^^^^^^^^^^^^^^^^^^^^^^^^^^^^^^^^^^^^^^^^^^^^^^^^^^^^^^^^^
INTERNALERROR>   File "C:\Users\User\AppData\Roaming\Python\Python312\site-packages\pluggy\_callers.py", line 167, in _multicall
INTERNALERROR>     raise exception
INTERNALERROR>   File "C:\Users\User\AppData\Roaming\Python\Python312\site-packages\pluggy\_callers.py", line 139, in _multicall
INTERNALERROR>     teardown.throw(exception)
INTERNALERROR>   File "C:\Users\User\AppData\Roaming\Python\Python312\site-packages\_pytest\logging.py", line 801, in pytest_runtestloop
INTERNALERROR>     return (yield)  # Run all the tests.
INTERNALERROR>             ^^^^^
INTERNALERROR>   File "C:\Users\User\AppData\Roaming\Python\Python312\site-packages\pluggy\_callers.py", line 139, in _multicall
INTERNALERROR>     teardown.throw(exception)
INTERNALERROR>   File "C:\Users\User\AppData\Roaming\Python\Python312\site-packages\_pytest\terminal.py", line 688, in pytest_runtestloop
INTERNALERROR>     result = yield
INTERNALERROR>              ^^^^^
INTERNALERROR>   File "C:\Users\User\AppData\Roaming\Python\Python312\site-packages\pluggy\_callers.py", line 152, in _multicall
INTERNALERROR>     teardown.send(result)
INTERNALERROR>   File "C:\Users\User\AppData\Roaming\Python\Python312\site-packages\pluggy\_callers.py", line 47, in run_old_style_hookwrapper
INTERNALERROR>     _warn_teardown_exception(hook_name, hook_impl, e)
INTERNALERROR>   File "C:\Users\User\AppData\Roaming\Python\Python312\site-packages\pluggy\_callers.py", line 73, in _warn_teardown_exception
INTERNALERROR>     warnings.warn(PluggyTeardownRaisedWarning(msg), stacklevel=6)
INTERNALERROR> pluggy.PluggyTeardownRaisedWarning: A plugin raised an exception during an old-style hookwrapper teardown.
INTERNALERROR> Plugin: _cov, Hook: pytest_runtestloop
INTERNALERROR> CoverageWarning: No data was collected. (no-data-collected)
INTERNALERROR> For more information see https://pluggy.readthedocs.io/en/stable/api_reference.html#pluggy.PluggyTeardownRaisedWarning

============================== 2 passed in 0.23s ==============================
